<?xml version="1.0" ?>

<robot xmlns:xacro="http://www.ros.org/wiki/xacro">

  <!-- Link base footprint -->
  <link name="base_footprint"/>
  <!-- Joint base footprint -->
  <joint name="base_joint" type="fixed">
      <parent link="base_footprint" />
      <child link="base_link" />
      <origin xyz="0 0 0.004" rpy="0 0 0" />
  </joint>

  <!-- Link base_link -->
  <link name="base_link">
    <inertial>
      <origin xyz="-0.00978934 8.10483e-16 0.0392801" rpy="0 0 0"/>
      <mass value="2.10059"/>
      <inertia ixx="0.00360353" ixy="0" ixz="0.000635006" iyy="0.00682291" iyz="0" izz="0.00795693"/>
    </inertial>
    <!-- Part base_link -->
    <visual>
      <origin xyz="0 0 0" rpy="0 -0 0"/>
      <geometry>
        <mesh filename="package://slambot_description/assets/base_link.stl"/>
      </geometry>
      <material name="base_link_material">
        <color rgba="0.231373 0.380392 0.705882 1"/>
      </material>
    </visual>
    <collision>
      <origin xyz="0 0 0" rpy="0 -0 0"/>
      <geometry>
        <mesh filename="package://slambot_description/assets/base_link.stl"/>
      </geometry>
    </collision>
  </link>

  <!-- Link rear_right_wheel_link -->
  <link name="rear_right_wheel_link">
    <inertial>
      <origin xyz="-8.65114e-09 5.12286e-09 -0.0132554" rpy="0 0 0"/>
      <mass value="0.0478503"/>
      <inertia ixx="1.60159e-05" ixy="-2.44085e-12" ixz="-8.19615e-12" iyy="1.60159e-05" iyz="1.09538e-11" izz="2.75064e-05"/>
    </inertial>
    <!-- Part rear_right_wheel_link -->
    <visual>
      <origin xyz="0 0 -0.0235" rpy="1.5708 -0 0"/>
      <geometry>
        <mesh filename="package://slambot_description/assets/wheel_link.stl"/>
      </geometry>
      <material name="wheel_link_material">
        <color rgba="0.647059 0.647059 0.647059 1"/>
      </material>
    </visual>
    <collision>
      <origin xyz="0 0 -0.0235" rpy="1.5708 -0 0"/>
      <geometry>
        <mesh filename="package://slambot_description/assets/wheel_link.stl"/>
      </geometry>
    </collision>
  </link>
  <!-- Joint from base_link to rear_right_wheel_link -->
  <joint name="rear_right_wheel_joint" type="continuous">
    <origin xyz="-0.075 -0.06 0.02" rpy="-1.5708 -0 0"/>
    <parent link="base_link"/>
    <child link="rear_right_wheel_link"/>
    <axis xyz="0 0 1"/>
    <limit effort="100" velocity="100"/>
  </joint>
  <!-- Link front_right_wheel_link -->
  <link name="front_right_wheel_link">
    <inertial>
      <origin xyz="-8.65114e-09 5.12286e-09 -0.0132554" rpy="0 0 0"/>
      <mass value="0.0478503"/>
      <inertia ixx="1.60159e-05" ixy="-2.44085e-12" ixz="-8.19615e-12" iyy="1.60159e-05" iyz="1.09538e-11" izz="2.75064e-05"/>
    </inertial>
    <!-- Part front_right_wheel_link -->
    <visual>
      <origin xyz="0 0 -0.0235" rpy="1.5708 -0 0"/>
      <geometry>
        <mesh filename="package://slambot_description/assets/wheel_link.stl"/>
      </geometry>
      <material name="wheel_link_2_material">
        <color rgba="0.647059 0.647059 0.647059 1"/>
      </material>
    </visual>
    <collision>
      <origin xyz="0 0 -0.0235" rpy="1.5708 -0 0"/>
      <geometry>
        <mesh filename="package://slambot_description/assets/wheel_link.stl"/>
      </geometry>
    </collision>
  </link>
  <!-- Joint from base_link to front_right_wheel_link -->
  <joint name="front_right_wheel_joint" type="continuous">
    <origin xyz="0.075 -0.06 0.02" rpy="-1.5708 -0 0"/>
    <parent link="base_link"/>
    <child link="front_right_wheel_link"/>
    <axis xyz="0 0 1"/>
    <limit effort="100" velocity="100"/>
  </joint>
  <!-- Link rear_left_wheel_link -->
  <link name="rear_left_wheel_link">
    <inertial>
      <origin xyz="-8.65114e-09 -5.12286e-09 0.0132554" rpy="0 0 0"/>
      <mass value="0.0478503"/>
      <inertia ixx="1.60159e-05" ixy="2.44085e-12" ixz="8.19615e-12" iyy="1.60159e-05" iyz="1.09538e-11" izz="2.75064e-05"/>
    </inertial>
    <!-- Part rear_left_wheel_link -->
    <visual>
      <origin xyz="0 0 0.0235" rpy="-1.5708 -0 0"/>
      <geometry>
        <mesh filename="package://slambot_description/assets/wheel_link.stl"/>
      </geometry>
      <material name="wheel_link_3_material">
        <color rgba="0.647059 0.647059 0.647059 1"/>
      </material>
    </visual>
    <collision>
      <origin xyz="0 0 0.0235" rpy="-1.5708 -0 0"/>
      <geometry>
        <mesh filename="package://slambot_description/assets/wheel_link.stl"/>
      </geometry>
    </collision>
  </link>
  <!-- Joint from base_link to rear_left_wheel_link -->
  <joint name="rear_left_wheel_joint" type="continuous">
    <origin xyz="-0.075 0.06 0.02" rpy="-1.5708 -0 0"/>
    <parent link="base_link"/>
    <child link="rear_left_wheel_link"/>
    <axis xyz="0 0 1"/>
    <limit effort="100" velocity="100"/>
  </joint>
  <!-- Link front_left_wheel_link -->
  <link name="front_left_wheel_link">
    <inertial>
      <origin xyz="-8.65114e-09 -5.12286e-09 0.0132554" rpy="0 0 0"/>
      <mass value="0.0478503"/>
      <inertia ixx="1.60159e-05" ixy="2.44085e-12" ixz="8.19615e-12" iyy="1.60159e-05" iyz="1.09538e-11" izz="2.75064e-05"/>
    </inertial>
    <!-- Part front_left_wheel_link -->
    <visual>
      <origin xyz="0 0 0.0235" rpy="-1.5708 -0 0"/>
      <geometry>
        <mesh filename="package://slambot_description/assets/wheel_link.stl"/>
      </geometry>
      <material name="wheel_link_4_material">
        <color rgba="0.647059 0.647059 0.647059 1"/>
      </material>
    </visual>
    <collision>
      <origin xyz="0 0 0.0235" rpy="-1.5708 -0 0"/>
      <geometry>
        <mesh filename="package://slambot_description/assets/wheel_link.stl"/>
      </geometry>
    </collision>
  </link>
  <!-- Joint from base_link to front_left_wheel_link -->
  <joint name="front_left_wheel_joint" type="continuous">
    <origin xyz="0.075 0.06 0.02" rpy="-1.5708 -0 0"/>
    <parent link="base_link"/>
    <child link="front_left_wheel_link"/>
    <axis xyz="0 0 1"/>
    <limit effort="100" velocity="100"/>
  </joint>

</robot>